Workbook

Sheet README
A1: Livrable 2 - Dossier EBIOS Risk Manager : GitLab
A2: Évaluation externe sur sources publiques. Date limite des preuves : 2026-10-04. Les scores sont des jugements d'analyste, pas des données internes de GitLab.
A4: Objet | B4: Documents de travail EBIOS RM inspectables, à la base du rapport principal. Chaque onglet correspond à un livrable d'atelier.
A5: Onglets | B5: AT1 Périmètre, Valeurs métier, Biens supports, Événements redoutés, Socle | AT2 Sources de risque, couples SR/OV | AT3 Écosystème, Scénarios stratégiques | AT4 Scénarios opérationnels | Registre des risques | AT5 Traitement, Suivi | Échelles
A6: Formules actives | B6: Le score de risque, le niveau de priorité et le niveau de menace de l'écosystème sont des formules. Modifiez un impact/une vraisemblance (cellules de saisie grises) et tout se recalcule.
A7: Convention de cellules | B7: Chiffres en gras sur fond gris clair = saisie de jugement modifiable. Cellules simples = texte ou formules. Niveaux de priorité : Critique >= 20, Élevé 15-19, Moyen 8-14, Faible <= 7.
A8: Traçabilité | B8: Risque -> Scénario stratégique (SS) -> Scénario opérationnel (OS) -> Événement redouté (ER) -> Valeur métier (VM) -> Exigence PSSI -> Action de la feuille de route (A-xx) -> Preuve (E-xx).
A9: Limite | B9: Ceci n'est ni un audit, ni un test d'intrusion, ni une évaluation de vulnérabilités. « Non vérifiable publiquement » ne signifie pas « absent ».

Sheet AT1_Perimetre
A1: Atelier 1 - Périmètre de l'étude
A3: Mission | B3: Fournir la plateforme d'orchestration intelligente pour le DevSecOps : gestion de code source, CI/CD, outils de sécurité et de conformité, et agents d'IA, livrée sous forme de GitLab.com (SaaS multi-tenant), GitLab Dedicated (SaaS mono-tenant) et logiciel auto-hébergé.
A4: Autorité de décision sur les risques (supposée) | B4: Responsable de la sécurité des systèmes d'information (RSSI, actuellement par intérim), sous la supervision du comité d'audit du conseil d'administration - décideurs supposés pour l'acceptation du risque dans cette étude.
A6: Dans le périmètre
B7: GitLab.com SaaS multi-tenant (plateforme de production, runners CI partagés, registres, fonctions d'IA).
B8: GitLab Dedicated, y compris le plan de contrôle Switchboard et les comptes AWS des tenants exploités par GitLab.
B9: Ingénierie produit et chaîne de livraison produisant le logiciel auto-hébergé et le code SaaS.
B10: Capacités d'IA (GitLab Duo / Duo Agent Platform) et dépendances envers les fournisseurs de modèles.
B11: Gouvernance de la sécurité, identité des collaborateurs et administration pouvant atteindre les éléments ci-dessus.
B12: Tiers et sous-traitants que GitLab déclare publiquement comme participant à la fourniture du service.
A14: Hors périmètre
B15: Instances auto-hébergées exploitées par les clients (responsabilité du client ; considérées uniquement comme effet d'écosystème).
B16: Dépôts, pipelines et configurations propres aux clients.
B17: Systèmes, configurations et personnels internes de GitLab (aucun accès interne ; sources publiques uniquement).
B18: JiHu (coentreprise chinoise, entité consolidée VIE) - citée comme entité de l'écosystème, non évaluée en profondeur.
B19: Tests techniques de toute nature (ni scan, ni test d'intrusion, ni exploitation).

Sheet AT1_ValeursMetier
A1: Atelier 1 - Valeurs métier
A3: ID | B3: Valeur métier | C3: Description | D3: Responsable (rôle supposé) | E3: Besoin de sécurité principal
A4: VM-01 | B4: Fourniture du service SaaS GitLab.com | C4: Plateforme hébergée multi-tenant pour dépôts, CI/CD, registres et gestion de projet, utilisée par des millions d'utilisateurs ; SLA de disponibilité mensuelle de 99,9 %. | D4: VP Infrastructure / Plateformes SaaS | E4: Disponibilité, Intégrité
A5: VM-02 | B5: Fourniture du service GitLab Dedicated | C5: SaaS mono-tenant pour clients régulés (dont Dedicated for Government), comptes AWS par tenant, plan de contrôle Switchboard. | D5: Ingénierie Dedicated | E5: Confidentialité, Intégrité, Disponibilité
A6: VM-03 | B6: Ingénierie produit et chaîne de livraison | C6: Code source, infrastructure de build et de release, dépôts de paquets et éléments de signature produisant le logiciel GitLab pour le SaaS et l'auto-hébergé (open-core, milliers de contributeurs externes). | D6: VP Ingénierie / Sécurité produit | E6: Intégrité, Authenticité
A7: VM-04 | B7: Contenus et secrets des clients | C7: Code source des clients, variables CI/CD, jetons d'accès, clés de déploiement, artefacts de conteneurs/paquets et données de projet hébergés par GitLab. | D7: Protection des données / Sécurité | E7: Confidentialité, Intégrité
A8: VM-05 | B8: Capacités d'IA (Duo / Duo Agent Platform) | C8: Assistants et agents autonomes d'IA agissant sur le code et les pipelines des clients, dépendant de fournisseurs de modèles tiers. | D8: Ingénierie IA / Sécurité de l'IA | E8: Intégrité, Confidentialité
A9: VM-06 | B9: Confiance, assurance et éligibilité aux marchés | C9: Certifications et attestations (SOC 2, ISO 27001/27017/27018/42001, FedRAMP), Trust Center, accès aux marchés publics et régulés. | D9: Assurance sécurité / Conformité | E9: Authenticité, Traçabilité
A10: VM-07 | B10: Opérations de sécurité, identité des collaborateurs et administration | C10: Réponse aux incidents, gestion et divulgation des vulnérabilités, identité des collaborateurs, outils d'administration et de support pour ~2 600 personnes en télétravail complet, y compris du personnel PEO et prestataire. | D10: Opérations de sécurité / IT | E10: Confidentialité, Intégrité

Sheet AT1_BiensSupports
A1: Atelier 1 - Biens supports
A3: ID | B3: Bien support | C3: Type | D3: Valeurs métier liées | E3: Preuves
A4: SA-01 | B4: Application Rails de GitLab.com, API et couche web | C4: Logiciel / application | D4: VM-01, VM-04 | E4: E-01, E-12
A5: SA-02 | B5: Stockage des dépôts Gitaly et bases de données | C5: Données / stockage | D5: VM-01, VM-04 | E5: E-12, E-13
A6: SA-03 | B6: Flottes de runners CI/CD partagés (runners hébergés par GitLab) | C6: Calcul / exécution | D6: VM-01, VM-04 | E6: E-02
A7: SA-04 | B7: Registres de conteneurs et de paquets | C7: Logiciel / données | D7: VM-01, VM-03, VM-04 | E7: E-01
A8: SA-05 | B8: Organisation et projets Google Cloud (us-east1 / us-central1) | C8: Infrastructure cloud | D8: VM-01 | E8: E-12, E-13, E-09
A9: SA-06 | B9: Architecture Cells (évolution de GitLab.com en cellules) | C9: Architecture | D9: VM-01 | E9: E-14
A10: SA-07 | B10: Comptes AWS de tenants Dedicated et VPC isolés | C10: Infrastructure cloud | D10: VM-02, VM-04 | E10: E-10, E-11
A11: SA-08 | B11: Plan de contrôle Switchboard et accès opérateurs Dedicated | C11: Plan de gestion | D11: VM-02 | E11: E-10
A12: SA-09 | B12: Dépôts sources du produit, pipelines CI, infrastructure de build et de signature | C12: Chaîne d'approvisionnement logicielle | D12: VM-03 | E12: E-01, E-02
A13: SA-10 | B13: Processus de contribution communautaire et dépendances tierces | C13: Processus / dépendance | D13: VM-03 | E13: E-01, E-02
A14: SA-11 | B14: Dépôts clients, variables CI, jetons, clés de déploiement | C14: Données | D14: VM-04 | E14: E-02, E-34
... A20: SA-17 | B20: Personnel PEO / prestataire et modèle de télétravail complet | C20: Personnes / organisation | D20: VM-07 | E20: E-01

Sheet AT1_EvenementsRedoutes
A1: Atelier 1 - Événements redoutés
A2: La gravité utilise l'échelle 1-5 de l'onglet « Echelles ». La gravité est une saisie sur fond gris.
A4: ID | B4: Événement redouté | C4: Valeurs métier | D4: DIC | E4: Gravité (1-5) | F4: Niveau | G4: Justification
A5: ER-01 | B5: Exfiltration à grande échelle de dépôts, jetons et secrets clients depuis GitLab.com | C5: VM-01, VM-04 | D5: C | E5: 5 | F5: =INDEX(Echelles!$B$5:$B$9,E5) -> Critique | G5: Le code source et les secrets CI de plus de 10 000 clients payants (dont plus de 50 % du Fortune 100) pourraient permettre la compromission en aval des clients ; notification de violation et exposition contractuelle.
A6: ER-02 | B6: Modification malveillante du code produit, du build ou des artefacts de release de GitLab | C6: VM-03 | D6: I | E6: 5 | F6: =INDEX(Echelles!$B$5:$B$9,E6) -> Critique | G6: Une release empoisonnée atteint le SaaS et chaque client auto-hébergé ; événement classique de chaîne d'approvisionnement logicielle à portée systémique.
A7: ER-03 | B7: Indisponibilité prolongée de GitLab.com ou perte de données irrécupérable | C7: VM-01 | D7: D | E7: 4 | F7: =INDEX(Echelles!$B$5:$B$9,E7) -> Majeur | G7: Les pipelines de livraison des clients s'arrêtent ; crédits SLA, perte de clients, atteinte à la réputation. La reprise après perte régionale repose sur reconstruction et restauration.
A8: ER-04 | B8: Compromission du plan de contrôle Dedicated ou de l'isolation des tenants | C8: VM-02 | D8: C, I | E8: 5 | F8: =INDEX(Echelles!$B$5:$B$9,E8) -> Critique | G8: Les tenants régulés et gouvernementaux partagent un plan opérateur ; une compromission du plan de contrôle serait multi-tenant par construction.
A9: ER-05 | B9: Fonction d'IA ou agent détourné pour fuiter des données ou injecter du code malveillant | C9: VM-05, VM-04 | D9: C, I | E9: 4 | F9: =INDEX(Echelles!$B$5:$B$9,E9) -> Majeur | G9: Les agents agissent avec les privilèges de l'utilisateur sur du code privé ; l'injection de prompt peut en faire des canaux d'exfiltration ou de falsification de code.
A10: ER-06 | B10: Perte ou expiration de certifications clés et de l'éligibilité aux marchés régulés | C10: VM-06 | D10: Authenticité | E10: 3 | F10: =INDEX(Echelles!$B$5:$B$9,E10) -> Modéré | G10: Des opinions d'audit avec réserves, une transition ISO manquée ou des difficultés FedRAMP bloqueraient les ventes publiques et régulées.
A11: ER-07 | B11: Vulnérabilité critique du produit massivement exploitée avant que les clients puissent corriger | C11: VM-03, VM-07 | D11: C, I, D | E11: 4 | F11: =INDEX(Echelles!$B$5:$B$9,E11) -> Majeur | G11: Les parcs auto-hébergés sont exposés dans les heures suivant un correctif ; GitLab subit l'impact de réputation et de support même si l'instance est gérée par le client.
A12: ER-08 | B12: Prise de contrôle d'identités privilégiées de collaborateurs ou d'administration | C12: VM-07, VM-01, VM-02 | D12: C, I | E12: 5 | F12: =INDEX(Echelles!$B$5:$B$9,E12) -> Critique | G12: L'identité privilégiée est le facilitateur commun de ER-01, ER-02 et ER-04.
A13: ER-09 | B13: Runners CI partagés détournés pour un impact inter-tenants ou un abus massif de ressources | C13: VM-01 | D13: C, D | E13: 4 | F13: =INDEX(Echelles!$B$5:$B$9,E13) -> Majeur | G13: Le code des clients s'exécutant sur l'infrastructure de GitLab, une défaillance d'isolation a des conséquences inter-tenants.
A14: ER-10 | B14: Divulgation involontaire d'informations sensibles via la transparence radicale | C14: VM-07, VM-03 | D14: C | E14: 3 | F14: =INDEX(Echelles!$B$5:$B$9,E14) -> Modéré | G14: Le handbook public, les trackers d'issues et la feuille de route ouverte peuvent fuiter des détails opérationnels sensibles ; le 10-K signale lui-même ce risque.

Sheet AT1_Socle
A1: Atelier 1 - Socle de sécurité
A2: Ce qui est démontré publiquement vs points de vigilance. L'absence de preuve publique n'est pas l'absence de mesure.
A4: Référentiel / ensemble de mesures | B4: État démontré publiquement | C4: Écart ou point de vigilance | D4: Preuves
A5: SOC 2 Type 2 (Sécurité, Confidentialité, Disponibilité) - GitLab.com et Dedicated | B5: En place ; rapports 2025 et lettre de continuité 2025-26 listés sur le Trust Center | C5: Les rapports sont soumis à NDA ; les exceptions éventuelles ne sont pas visibles de l'extérieur | D5: E-05
A6: ISO/IEC 27001 / 27017 / 27018 (sécurité du cloud et données personnelles dans le cloud) | B6: Certificat listé sur le Trust Center ; couvre GitLab.com et Dedicated | C6: D'anciennes pages publiques citent l'édition 2013 ; les certificats ISO 27001:2013 ont cessé d'être valides après l'échéance de transition du 31 oct. 2025 - les pages publiques devraient être rapprochées de l'édition 2022 | D6: E-05, E-07, E-08
A7: ISO/IEC 42001:2023 (système de management de l'IA) | B7: Certification annoncée sur le Trust Center | C7: Périmètre (quelles fonctions d'IA) non détaillé publiquement | D7: E-05, E-06
A8: FedRAMP Moderate (Dedicated for Government) ; High en perspective | B8: Listé comme actuel / prévu dans le handbook | C8: Périmètre d'autorisation et résultats de surveillance continue non détaillés publiquement | D8: E-06, E-07
A9: GitLab Control Framework rapproché de SOC 2, ISO 27001, PCI, FedRAMP | B9: Décrit publiquement | C9: Résultats des tests de contrôles non publics | D9: E-36
A10: Politique de gestion des accès (moindre privilège, approbations, revues, retrait des droits, exceptions) | B10: Document contrôlé public avec références de contrôles de type NIST | C10: Fréquence des revues et indicateurs de couverture non publiés | D10: E-16, E-17
A11: Divulgation des vulnérabilités (bug bounty HackerOne, security.txt, CVE avec CWE, correctifs mensuels + critiques) | B11: Documenté publiquement et visiblement en fonctionnement | C11: Délais de correction et taux d'adoption des correctifs par les clients non publiés | D11: E-18, E-19, E-22
A12: Engagement CISA Secure by Design (MFA, réduction des mots de passe par défaut, correctifs, politique de divulgation) | B12: Rapport d'avancement publié en juin 2025 ; déploiement du MFA par défaut annoncé comme à venir | C12: Achèvement du MFA par défaut non confirmé dans les sources examinées | D12: E-18
A13: Reprise après sinistre (Game Days trimestriels, sauvegardes multi-régions, tests de restauration quotidiens de la base, objectifs RTO/RPO) | B13: Politique publiée dans le handbook ; SLA Dedicated avec RTO/RPO | C13: Les documents de conception décrivent une exploitation GitLab.com mono-région et indiquent que la reprise régionale n'avait pas été validée de bout en bout lors de la rédaction ; état actuel inconnu | D13: E-12, E-13, E-14, E-15
A14: Gouvernance de la sécurité (programme piloté par le RSSI, plus de 120 praticiens, ERM piloté par l'Audit interne, supervision du comité d'audit) | B14: Publié dans l'Item 1C du 10-K | C14: Poste de RSSI laissé vacant le 26 févr. 2026 ; RSSI par intérim en place durant la recherche | D14: E-03, E-04

Sheet AT2_SourcesRisque
A1: Atelier 2 - Sources de risque
A3: ID | B3: Source de risque | C3: Motivation / objectif | D3: Ressources | E3: Activité / capacité | F3: Décision | G3: Justification (preuves publiques)
A4: SR-1 | B4: Acteurs étatiques / menaces persistantes avancées (APT) | C4: Espionnage, pré-positionnement, accès au code de clients gouvernementaux et de défense | D4: Très élevées | E4: Très élevée | F4: Retenue | G4: GitLab héberge du code pour des clients du secteur public, proches de la défense et d'infrastructures critiques ; FedRAMP/Dedicated for Government signale cette clientèle.
A5: SR-2 | B5: Cybercriminalité organisée (extorsion, vol d'identifiants et de secrets) | C5: Gain financier : rançon, revente de secrets/accès, cryptominage | D5: Élevées | E5: Très élevée | F5: Retenue | G5: L'activité d'infostealers, le vol de session et la collecte de secrets exposés sont courants ; les secrets CI ont une forte valeur.
A6: SR-3 | B6: Exploiteurs opportunistes de masse et opérateurs de botnets | C6: Gains rapides sur des vulnérabilités nouvellement divulguées | D6: Moyennes | E6: Très élevée | F6: Retenue | G6: Exploitation observée dans les heures suivant la publication du correctif de septembre 2026 ; inscriptions KEV en 2024 et 2026.
A7: SR-4 | B7: Interne malveillant ou contraint (salarié, prestataire, PEO ou personnel de support externalisé) | C7: Gain financier, rancœur, contrainte | D7: Moyennes | E7: Moyenne | F7: Retenue | G7: Un personnel en télétravail engagé par embauche directe, PEO et prestataires élargit la surface d'action des internes.
A8: SR-5 | B8: Contributeur open source malveillant / mainteneur compromis | C8: Insertion de porte dérobée, levier sur la chaîne d'approvisionnement | D8: Élevées | E8: Moyenne | F8: Retenue | G8: Modèle open-core avec plus de 5 200 contributeurs ; le 10-K cite les attaques de chaîne d'approvisionnement via le code communautaire comme risque significatif.
A9: SR-6 | B9: Hacktivistes | C9: Perturbation, publicité | D9: Faibles | E9: Moyenne | F9: Retenue (faible) | G9: DDoS ou défiguration possibles ; capacité soutenue limitée.
A10: SR-7 | B10: Utilisateurs malveillants de la plateforme (abus de l'offre gratuite et du calcul partagé) | C10: Calcul gratuit, anonymat, attaque latérale d'autres tenants | D10: Faibles | E10: Élevée | F10: Retenue | G10: Le code fourni par les clients s'exécute par conception sur l'infrastructure GitLab (10-K).
A11: SR-8 | B11: Adversaires assistés par IA / acteurs d'injection de prompt | C11: Vol de données et manipulation de code via les agents d'IA | D11: Moyennes | E11: Élevée | F11: Retenue | G11: Des recherches documentées montrent une injection de prompt indirecte contre Duo ; le 10-K cite des vecteurs d'attaque propres à l'IA.
A12: SR-9 | B12: Concurrents et renseignement économique hostile | C12: Intelligence économique | D12: Moyennes | E12: Faible | F12: Non retenue | G12: La culture publique par défaut réduit la valeur additionnelle d'un vol discret ; couvert par SR-1/ER-10 le cas échéant.

Sheet AT2_SR_OV
A1: Atelier 2 - Couples source de risque / objectif visé
A2: Pertinence 1 (faible) - 4 (très élevée). Les couples de pertinence >= 2 sont retenus pour l'atelier 3.
A4: Couple | B4: Source de risque | C4: Objectif visé (OV) | D4: Événements redoutés liés | E4: Pertinence (1-4) | F4: Retenu
A5: C-01 | B5: SR-1 | C5: Voler code source, secrets et architectures de clients à forte valeur via GitLab.com | D5: ER-01, ER-08 | E5: 4 | F5: =IF(E5>=2,"Oui","Non") -> Oui
A6: C-02 | B6: SR-2 | C6: Extorquer ou monétiser des secrets et accès volés en compromettant des identités privilégiées | D6: ER-08, ER-01 | E6: 4 | F6: =IF(E6>=2,"Oui","Non") -> Oui
A7: C-03 | B7: SR-5 | C7: Insérer une porte dérobée dans le produit ou la chaîne de release de GitLab pour un accès en aval | D7: ER-02 | E7: 3 | F7: =IF(E7>=2,"Oui","Non") -> Oui
A8: C-04 | B8: SR-1 | C8: Se pré-positionner dans la chaîne de build et de release de GitLab pour de futures opérations de chaîne d'approvisionnement | D8: ER-02 | E8: 3 | F8: =IF(E8>=2,"Oui","Non") -> Oui
A9: C-05 | B9: SR-3 | C9: Exploiter en masse les vulnérabilités produit nouvellement divulguées (auto-hébergé et SaaS) | D9: ER-07, ER-01 | E9: 4 | F9: =IF(E9>=2,"Oui","Non") -> Oui
A10: C-06 | B10: SR-8 | C10: Exfiltrer du code privé ou manipuler du code via les assistants et agents d'IA | D10: ER-05 | E10: 3 | F10: =IF(E10>=2,"Oui","Non") -> Oui
A11: C-07 | B11: SR-7 | C11: Détourner les runners partagés pour voler des ressources ou s'évader vers d'autres tenants | D11: ER-09 | E11: 3 | F11: =IF(E11>=2,"Oui","Non") -> Oui
A12: C-08 | B12: SR-4 | C12: Détourner un accès administratif ou de support légitime pour vol ou sabotage | D12: ER-08, ER-01 | E12: 2 | F12: =IF(E12>=2,"Oui","Non") -> Oui
A13: C-09 | B13: SR-6 | C13: Perturber la disponibilité de GitLab.com à des fins de publicité | D13: ER-03 | E13: 2 | F13: =IF(E13>=2,"Oui","Non") -> Oui
A14: C-10 | B14: SR-2 | C14: Détruire ou chiffrer des données de production à des fins d'extorsion | D14: ER-03 | E14: 2 | F14: =IF(E14>=2,"Oui","Non") -> Oui
A15: C-11 | B15: SR-1 | C15: Compromettre le plan de contrôle Dedicated pour atteindre des tenants régulés | D15: ER-04 | E15: 2 | F15: =IF(E15>=2,"Oui","Non") -> Oui
A16: C-12 | B16: SR-9 | C16: Intelligence économique sur les feuilles de route internes | D16: ER-10 | E16: 1 | F16: =IF(E16>=2,"Oui","Non") -> Non

Sheet AT3_Ecosysteme
A1: Atelier 3 - Cartographie de l'écosystème
A2: Niveau de menace = (Dépendance x Pénétration) / (Maturité x Confiance), chacun noté 1-4. Critique >= 2,0 ; Élevé 1,0-1,99 ; Moyen 0,5-0,99 ; Faible < 0,5.
A4: Partie prenante | B4: Catégorie | C4: Dépendance | D4: Pénétration | E4: Maturité cyber | F4: Confiance | G4: Niveau de menace | H4: Niveau | I4: Commentaire
A5: Dépendances open source et contributeurs externes | B5: Communauté / chaîne d'approvisionnement | C5: 4 | D5: 3 | E5: 2 | F5: 2 | G5: =ROUND((C5*D5)/(E5*F5),2) -> 3 | H5: =IF(G5>=2,"Critique",IF(G5>=1,"Élevé",IF(G5>=0.5,"Moyen","Faible"))) -> Critique | I5: Surface de contributeurs et de dépendances vaste et peu gouvernée alimentant le produit (10-K : plus de 5 200 contributeurs ; risque de chaîne d'approvisionnement open source cité).
A6: Clients et utilisateurs de l'offre gratuite (tenants, intégrations, runners personnalisés) | B6: Clients / utilisateurs | C6: 2 | D6: 4 | E6: 2 | F6: 1 | G6: =ROUND((C6*D6)/(E6*F6),2) -> 4 | H6: =IF(G6>=2,"Critique",IF(G6>=1,"Élevé",IF(G6>=0.5,"Moyen","Faible"))) -> Critique | I6: Exécutent du code arbitraire sur l'infrastructure de GitLab ; la confiance est structurellement faible.
A7: SaaS d'entreprise et fournisseurs d'identité (IdP, postes, collaboration) | B7: Prestataires de services critiques | C7: 4 | D7: 4 | E7: 3 | F7: 3 | G7: =ROUND((C7*D7)/(E7*F7),2) -> 1.78 | H7: =IF(G7>=2,"Critique",IF(G7>=1,"Élevé",IF(G7>=0.5,"Moyen","Faible"))) -> Élevé | I7: Non détaillés publiquement ; supposés détenir les clés de l'identité des collaborateurs.
A8: Fournisseurs de modèles d'IA et partenaires de passerelle IA | B8: Prestataires de services critiques | C8: 3 | D8: 3 | E8: 3 | F8: 2 | G8: =ROUND((C8*D8)/(E8*F8),2) -> 1.5 | H8: =IF(G8>=2,"Critique",IF(G8>=1,"Élevé",IF(G8>=0.5,"Moyen","Faible"))) -> Élevé | I8: Le 10-K et la liste des sous-traitants montrent une dépendance à des modèles tiers (p. ex. Google, AWS, OpenAI) ; risque de concentration et de changement de conditions.
A9: PEO, prestataires et personnel en télétravail | B9: Personnes / effectif | C9: 3 | D9: 3 | E9: 2 | F9: 3 | G9: =ROUND((C9*D9)/(E9*F9),2) -> 1.5 | H9: =IF(G9>=2,"Critique",IF(G9>=1,"Élevé",IF(G9>=0.5,"Moyen","Faible"))) -> Élevé | I9: Modèles d'employeur de référence et de prestation dans de nombreuses juridictions ; visibilité inégale des mesures.
A10: Google Cloud (hébergement de GitLab.com) | B10: Hyperscaler | C10: 4 | D10: 4 | E10: 4 | F10: 3 | G10: =ROUND((C10*D10)/(E10*F10),2) -> 1.33 | H10: =IF(G10>=2,"Critique",IF(G10>=1,"Élevé",IF(G10>=0.5,"Moyen","Faible"))) -> Élevé | I10: GitLab.com s'exécute dans GCP us-east1 sur plusieurs zones de disponibilité ; dépendance infrastructurelle profonde.
A11: Amazon Web Services (hébergement de Dedicated) | B11: Hyperscaler | C11: 3 | D11: 4 | E11: 4 | F11: 3 | G11: =ROUND((C11*D11)/(E11*F11),2) -> 1 | H11: =IF(G11>=2,"Critique",IF(G11>=1,"Élevé",IF(G11>=0.5,"Moyen","Faible"))) -> Élevé | I11: Comptes AWS par tenant sous une organisation mère GitLab ; Switchboard les pilote.
A12: Sous-traitants de support et de processus métier (p. ex. ticketing, recherche, analytique, support externalisé) | B12: Sous-traitants | C12: 2 | D12: 3 | E12: 3 | F12: 3 | G12: =ROUND((C12*D12)/(E12*F12),2) -> 0.67 | H12: =IF(G12>=2,"Critique",IF(G12>=1,"Élevé",IF(G12>=0.5,"Moyen","Faible"))) -> Moyen | I12: La liste publique de sous-traitants inclut des fournisseurs de ticketing, recherche, chaînes de données et support externalisé.
A13: JiHu (coentreprise chinoise, entité consolidée VIE) | B13: Affilié | C13: 1 | D13: 2 | E13: 2 | F13: 2 | G13: =ROUND((C13*D13)/(E13*F13),2) -> 0.5 | H13: =IF(G13>=2,"Critique",IF(G13>=1,"Élevé",IF(G13>=0.5,"Moyen","Faible"))) -> Moyen | I13: Mentionnée dans le 10-K ; détails de la relation non publics - notation à faible confiance.
A14: Partenaires, revendeurs et intégrateurs | B14: Partenaires | C14: 2 | D14: 2 | E14: 3 | F14: 3 | G14: =ROUND((C14*D14)/(E14*F14),2) -> 0.44 | H14: =IF(G14>=2,"Critique",IF(G14>=1,"Élevé",IF(G14>=0.5,"Moyen","Faible"))) -> Faible | I14: Canal de vente et de livraison ; accès technique limité.
A15: Chercheurs en sécurité et plateforme de bug bounty | B15: Communauté / assurance | C15: 2 | D15: 2 | E15: 4 | F15: 3 | G15: =ROUND((C15*D15)/(E15*F15),2) -> 0.33 | H15: =IF(G15>=2,"Critique",IF(G15>=1,"Élevé",IF(G15>=0.5,"Moyen","Faible"))) -> Faible | I15: Relation bénéfique ; incluse par exhaustivité (HackerOne).

Sheet AT3_ScenariosStrat
A1: Atelier 3 - Scénarios stratégiques
A2: Gravité = gravité du pire événement redouté atteint (1-5).
A3: ID | B3: Scénario stratégique | C3: Couples SR/OV | D3: Événements redoutés | E3: Chemin dans l'écosystème | F3: Gravité | G3: Description du chemin
A4: SS-01 | B4: Compromission d'identité privilégiée conduisant à un accès de production et à une exfiltration massive | C4: C-01, C-02 | D4: ER-08, ER-01 | E4: SaaS d'entreprise et fournisseurs d'identité ; postes d'un personnel en télétravail | F4: 5 | G4: L'adversaire vole les identifiants ou sessions d'un ingénieur/opérateur privilégié (infostealer, hameçonnage, vol de jeton) et utilise les consoles de production ou cloud pour extraire des données de tenants.
A5: SS-02 | B5: Compromission de la chaîne d'approvisionnement logicielle du produit GitLab | C5: C-03, C-04 | D5: ER-02 | E5: Contributeurs et dépendances open source ; outillage de build/release | F5: 5 | G5: L'adversaire subvertit un mainteneur, une dépendance ou une étape de build de sorte qu'une modification malveillante soit livrée au SaaS et aux clients auto-hébergés.
A6: SS-03 | B6: Exploitation d'une vulnérabilité produit critique (zero-day ou N-day) | C6: C-05 | D6: ER-01, ER-07 | E6: Parcs auto-hébergés des clients ; fenêtre de correction de GitLab.com | F6: 5 | G6: Une faille pré-authentification (p. ex. traversée de chemin ou désérialisation) est instrumentalisée à partir du différentiel de correctif ; le SaaS est corrigé en premier mais les clients auto-hébergés restent exposés.
A7: SS-04 | B7: Une compromission ou panne d'un cloud ou sous-traitant se propage aux services GitLab | C7: C-10 | D7: ER-03, ER-01 | E7: Google Cloud, AWS, fournisseurs d'IA, sous-traitants de support | F7: 4 | G7: Une défaillance ou violation chez un fournisseur critique se propage à GitLab.com, Dedicated ou aux fonctions d'IA.
A8: SS-05 | B8: Détournement d'agents d'IA par injection de prompt indirecte ou jetons sur-dimensionnés | C8: C-06 | D8: ER-05 | E8: Fournisseurs de modèles d'IA ; contenus clients traités par les agents | F8: 4 | G8: Des instructions cachées dans des issues, merge requests ou du code orientent Duo/les agents vers la fuite de données privées ou l'altération de code ; les jetons MCP/agent dépassent leur périmètre prévu.
A9: SS-06 | B9: Compromission du plan de contrôle Dedicated | C9: C-11 | D9: ER-04 | E9: AWS ; opérateurs Switchboard | F9: 5 | G9: Des identifiants d'opérateur ou une faille du plan de gestion donnent accès à plusieurs environnements mono-tenant.
A10: SS-07 | B10: Attaque destructrice, DDoS ou défaillance régionale avec reprise lente | C10: C-09, C-10 | D10: ER-03 | E10: Google Cloud ; infrastructures DDoS | F10: 4 | G10: Panne prolongée ou perte de données car la reprise régionale n'est que partiellement validée de bout en bout.
A11: SS-08 | B11: Usage abusif d'un accès administratif ou de support par un interne | C11: C-08 | D11: ER-08, ER-01 | E11: PEO, prestataires, support externalisé | F11: 4 | G11: Une personne de confiance abuse de son accès légitime.
A12: SS-09 | B12: Abus de runners partagés et évasion entre tenants | C12: C-07 | D12: ER-09 | E12: Clients et utilisateurs de l'offre gratuite | F12: 4 | G12: Des jobs de pipeline malveillants tentent évasion, capture de secrets ou détournement de ressources.
A13: SS-10 | B13: Défaut de continuité de gouvernance affaiblissant l'assurance et la certification | C13: - | D13: ER-06 | E13: Auditeurs ; organismes de certification | F13: 3 | G13: Transition de direction et croissance rapide pèsent sur le fonctionnement des mesures, les transitions de normes et la production de preuves (scénario indirect, hors attaque).
A14: SS-11 | B14: Reconnaissance et fuite via handbook, issues et feuille de route publics | C14: C-12 | D14: ER-10 | E14: Communauté publique ; concurrents | F14: 3 | G14: Un contenu public par défaut expose involontairement des détails opérationnels ou de sécurité utiles aux attaquants.

Sheet AT4_Operationnels
A1: Atelier 4 - Scénarios opérationnels (chemins d'attaque EBIOS « Connaître / Rentrer / Trouver / Exploiter »)
A2: Les références ATT&CK sont indicatives. La vraisemblance est une saisie sur fond gris et alimente le registre des risques.
A3: OS | B3: SS | C3: Scénario | D3: Risque | E3: Vraisemblance (1-5) | F3: Phase | G3: Étape d'attaque | H3: Technique ATT&CK | I3: Mesures publiques observées | J3: Faiblesse / point de vigilance
A4: OS-01 | B4: SS-01 | C4: Le vol de session d'un ingénieur privilégié conduit à l'extraction de données de production | D4: R-01 | E4: 4 | F4: Connaître | G4: Profiler les ingénieurs et opérateurs via le handbook public, les offres d'emploi, les réseaux sociaux et l'activité open source. | H4: T1591 Gather Victim Org Information | I4: Politique d'accès au moindre privilège avec approbations, revues et retrait des droits (E-16, E-17) ; assurance SOC 2 / ISO 27001 (E-05) ; équipe de sécurité de plus de 120 personnes et supervision du comité d'audit (E-03). | J4: La protection des sessions privilégiées (MFA résistant à l'hameçonnage, liaison à l'appareil, durée de jeton courte) et l'élévation juste-à-temps ne sont pas démontrées publiquement. Des données de notation externe signalent des détections d'infostealers sur des systèmes associés à l'organisation (E-29, indicateur seulement).
A5: OS-01 | B5: SS-01 | C5: Le vol de session d'un ingénieur privilégié conduit à l'extraction de données de production | D5: R-01 | F5: Rentrer | G5: Un infostealer ou un hameçonnage fournit identifiants et cookies de session actifs depuis un poste distant. | H5: T1566 Phishing / T1539 Steal Web Session Cookie
A6: OS-01 | B6: SS-01 | C6: Le vol de session d'un ingénieur privilégié conduit à l'extraction de données de production | D6: R-01 | F6: Trouver | G6: Utiliser l'identité volée pour atteindre le SSO, les consoles cloud, bastions ou outils d'administration ; énumérer les accès de production et les secrets. | H6: T1078 Valid Accounts / T1552 Unsecured Credentials
A7: OS-01 | B7: SS-01 | C7: Le vol de session d'un ingénieur privilégié conduit à l'extraction de données de production | D7: R-01 | F7: Exploiter | G7: Copier dépôts, variables CI ou instantanés de base vers un stockage contrôlé par l'attaquant ; éventuellement installer de la persistance. | H7: T1213 Data from Information Repositories / T1567 Exfiltration over Web Service
A8: OS-02 | B8: SS-02 | C8: Un mainteneur ou une dépendance compromis empoisonne la chaîne de release | D8: R-03 | E8: 3 | F8: Connaître | G8: Identifier les mainteneurs, l'outillage de build et le rythme de release (open-core, releases mensuelles, feuille de route publique). | H8: T1592 Gather Victim Host Information | I8: Revue de code et transparence open source ; programme HackerOne (E-18) ; rythme de releases mensuelles avec correctifs de sécurité (E-01, E-19). | J8: La provenance, la signature, les builds hermétiques et l'approbation de release à deux personnes ne sont pas documentées publiquement dans les sources examinées. Le 10-K cite les attaques de chaîne d'approvisionnement via le code communautaire comme risque significatif (E-02).
A9: OS-02 | B9: SS-02 | C9: Un mainteneur ou une dépendance compromis empoisonne la chaîne de release | D9: R-03 | F9: Rentrer | G9: Prendre le contrôle d'un compte de contributeur/mainteneur ou publier une version malveillante d'une dépendance ; soumettre une modification qui passe la revue. | H9: T1195.002 Compromise Software Supply Chain / T1078 Valid Accounts
A10: OS-02 | B10: SS-02 | C10: Un mainteneur ou une dépendance compromis empoisonne la chaîne de release | D10: R-03 | F10: Trouver | G10: Localiser les runners de build, clés de signature ou identifiants de publication de paquets. | H10: T1552 Unsecured Credentials
A11: OS-02 | B11: SS-02 | C11: Un mainteneur ou une dépendance compromis empoisonne la chaîne de release | D11: R-03 | F11: Exploiter | G11: Injecter du code dans un artefact de release ou un paquet ; livrer au SaaS et aux clients auto-hébergés. | H11: T1195 Supply Chain Compromise
A12: OS-03 | B12: SS-03 | C12: Une vulnérabilité pré-authentification est instrumentalisée dans les heures suivant la publication du correctif | D12: R-02 | E12: 4 | F12: Connaître | G12: Surveiller les releases de correctifs de GitLab et les différentiels de dépôt public pour repérer les correctifs de sécurité. | H12: T1588.006 Obtain Capabilities: Vulnerabilities | I12: GitLab.com corrigé au moment de la release (E-22) ; divulgation coordonnée, CVE avec CWE et releases de correctifs critiques (E-18, E-19) ; rétroportage vers d'anciennes branches (E-25). | J12: Failles critiques récurrentes : CVE-2023-7028 (KEV, 2024) et CVE-2026-85706 (CVSS 10, KEV, sept. 2026, exploitée en quelques jours), plus d'autres correctifs RCE critiques le 23 sept. 2026 (E-20, E-22, E-23, E-24, E-26). L'adoption des correctifs par les clients échappe au contrôle de GitLab (E-21).
A13: OS-03 | B13: SS-03 | C13: Une vulnérabilité pré-authentification est instrumentalisée dans les heures suivant la publication du correctif | D13: R-02 | F13: Rentrer | G13: Rétro-concevoir le correctif et scanner Internet à la recherche d'instances non corrigées ou sonder les frontaux SaaS. | H13: T1190 Exploit Public-Facing Application
A14: OS-03 | B14: SS-03 | C14: Une vulnérabilité pré-authentification est instrumentalisée dans les heures suivant la publication du correctif | D14: R-02 | F14: Trouver | G14: Lire fichiers de configuration, paramètres SSH et identifiants sur le serveur. | H14: T1552 Unsecured Credentials
A15: OS-03 | B15: SS-03 | C15: Une vulnérabilité pré-authentification est instrumentalisée dans les heures suivant la publication du correctif | D15: R-02 | F15: Exploiter | G15: Réutiliser les secrets collectés pour pivoter vers le code source, la CI et les environnements en aval. | H15: T1078 Valid Accounts / T1213 Data from Information Repositories
A16: OS-04 | B16: SS-05 | C16: L'injection de prompt indirecte oriente Duo ou un agent vers l'exfiltration de code privé | D16: R-06 | E16: 4 | F16: Connaître | G16: Étudier le comportement des fonctions d'IA, le contexte accessible (issues, merge requests, code) et les permissions d'outils des agents. | H16: T1592 Gather Victim Host Information | I16: Certification ISO 42001 (E-05) ; AI Transparency Center (E-05) ; fournisseur de protection contre l'injection de prompt listé comme sous-traitant (E-09) ; corrections de failles Duo signalées (E-27). | J16: Une recherche indépendante a démontré l'exfiltration de code privé (E-27) ; les correctifs de septembre 2026 incluent une désérialisation CVSS 9,9 atteignable via l'accès à Duo Chat et une faille d'application du périmètre des jetons MCP (E-23, E-26). L'autonomie croissante des agents étend la surface (E-01).
A17: OS-04 | B17: SS-05 | C17: L'injection de prompt indirecte oriente Duo ou un agent vers l'exfiltration de code privé | D17: R-06 | F17: Rentrer | G17: Placer des instructions cachées dans un projet public, un commentaire ou une merge request que l'assistant de la victime lira. | H17: T1565 Data Manipulation / T1204 User Execution
A18: OS-04 | B18: SS-05 | C18: L'injection de prompt indirecte oriente Duo ou un agent vers l'exfiltration de code privé | D18: R-06 | F18: Trouver | G18: L'agent suit les instructions injectées avec les privilèges de la victime et atteint dépôts privés ou jetons. | H18: T1213 Data from Information Repositories
A19: OS-04 | B19: SS-05 | C19: L'injection de prompt indirecte oriente Duo ou un agent vers l'exfiltration de code privé | D19: R-06 | F19: Exploiter | G19: Un canal de sortie (balisage, liens, appels) fuite du code ou des secrets ; ou l'agent propose/valide du code malveillant. | H19: T1567 Exfiltration over Web Service
A20: OS-05 | B20: SS-06 | C20: Des identifiants d'opérateur ou une faille du plan de contrôle donnent une portée multi-tenant dans Dedicated | D20: R-07 | E20: 2 | F20: Connaître | G20: Étudier l'architecture publique de Dedicated (Switchboard, comptes AWS de tenants, organisation mère). | H20: T1590 Gather Victim Network Information | I20: Isolation mono-tenant, comptes AWS et VPC par tenant, reprise Geo, PrivateLink optionnel (E-10, E-11) ; SOC 2 et FedRAMP Moderate pour Government (E-05, E-06). | J20: Le durcissement du plan de contrôle, les limites de rayon d'impact entre tenants et le modèle d'accès des opérateurs ne sont pas détaillés publiquement.
A21: OS-05 | B21: SS-06 | C21: Des identifiants d'opérateur ou une faille du plan de contrôle donnent une portée multi-tenant dans Dedicated | D21: R-07 | F21: Rentrer | G21: Compromettre une identité d'opérateur ou exploiter le plan de gestion. | H21: T1078 Valid Accounts / T1190 Exploit Public-Facing Application
A22: OS-05 | B22: SS-06 | C22: Des identifiants d'opérateur ou une faille du plan de contrôle donnent une portée multi-tenant dans Dedicated | D22: R-07 | F22: Trouver | G22: Énumérer les comptes de tenants sous l'organisation mère ; assumer des rôles. | H22: T1199 Trusted Relationship
A23: OS-05 | B23: SS-06 | C23: Des identifiants d'opérateur ou une faille du plan de contrôle donnent une portée multi-tenant dans Dedicated | D23: R-07 | F23: Exploiter | G23: Lire ou modifier données et configuration des tenants ; perturber la reprise (secondaire Geo). | H23: T1530 Data from Cloud Storage / T1485 Data Destruction
A24: OS-06 | B24: SS-07 | C24: Une perte régionale ou une attaque destructrice rencontre une reprise régionale non validée | D24: R-05 | E24: 3 | F24: Connaître | G24: Identifier l'empreinte mono-région (us-east1) et les dépendances. | H24: T1590 Gather Victim Network Information | I24: Game Days trimestriels, sauvegardes multi-régions et tests de restauration quotidiens de la base (E-12) ; SLA Dedicated avec RTO/RPO (E-15) ; travaux d'architecture Cells (E-14). | J24: Les documents de conception notent une exploitation mono-région et que la reprise régionale n'avait pas été validée de bout en bout lors de la rédaction (E-13). L'état actuel et l'immutabilité des sauvegardes ne sont pas indiqués publiquement.
A25: OS-06 | B25: SS-07 | C25: Une perte régionale ou une attaque destructrice rencontre une reprise régionale non validée | D25: R-05 | F25: Rentrer | G25: DDoS ou accès aux identités de sauvegarde/restauration ; ou événement de région cloud supprimant la capacité primaire. | H25: T1498 Network Denial of Service / T1078 Valid Accounts
A26: OS-06 | B26: SS-07 | C26: Une perte régionale ou une attaque destructrice rencontre une reprise régionale non validée | D26: R-05 | F26: Trouver | G26: Localiser les stockages de sauvegarde et l'outillage de reprise. | H26: T1490 Inhibit System Recovery
A27: OS-06 | B27: SS-07 | C27: Une perte régionale ou une attaque destructrice rencontre une reprise régionale non validée | D27: R-05 | F27: Exploiter | G27: Supprimer ou chiffrer les données ; forcer une reprise par reconstruction et restauration. | H27: T1485 Data Destruction / T1486 Data Encrypted for Impact
A28: OS-07 | B28: SS-09 | C28: Un job malveillant sur un runner partagé tente l'évasion ou la capture de secrets | D28: R-09 | E28: 3 | F28: Connaître | G28: Étudier les types d'exécuteurs de runners et le comportement de la flotte partagée. | H28: T1592 Gather Victim Host Information | I28: Le 10-K reconnaît le risque d'exécution de code et des mesures d'atténuation comme les limites de l'offre gratuite (E-02) ; couverture SOC 2 du SaaS (E-05). | J28: La conception de l'isolation des runners et les indicateurs de détection d'abus ne sont pas vérifiés publiquement dans les sources examinées.
A29: OS-07 | B29: SS-09 | C29: Un job malveillant sur un runner partagé tente l'évasion ou la capture de secrets | D29: R-09 | F29: Rentrer | G29: Soumettre un job CI avec une charge construite depuis un compte de l'offre gratuite. | H29: T1059 Command and Scripting Interpreter
A30: OS-07 | B30: SS-09 | C30: Un job malveillant sur un runner partagé tente l'évasion ou la capture de secrets | D30: R-09 | F30: Trouver | G30: Sonder l'hôte du runner, les services de métadonnées et les jobs voisins. | H30: T1611 Escape to Host / T1552 Unsecured Credentials
A31: OS-07 | B31: SS-09 | C31: Un job malveillant sur un runner partagé tente l'évasion ou la capture de secrets | D31: R-09 | F31: Exploiter | G31: Capturer les secrets d'autres tenants ou détourner du calcul pour du minage. | H31: T1496 Resource Hijacking
A32: OS-08 | B32: SS-04 | C32: Un incident chez un sous-traitant ou hyperscaler se propage à GitLab | D32: R-04 | E32: 3 | F32: Connaître | G32: Lire la liste publique de sous-traitants de GitLab et les pages d'architecture. | H32: T1591 Gather Victim Org Information | I32: Liste publique de sous-traitants avec notification des changements (E-09) ; ISO 27017/27018 (E-05). | J32: La profondeur de la diligence, les limites de concentration et les plans de sortie ne sont pas vérifiables publiquement ; le 10-K indique que GitLab peut être tenue responsable des défaillances de tiers (E-02).
A33: OS-08 | B33: SS-04 | C33: Un incident chez un sous-traitant ou hyperscaler se propage à GitLab | D33: R-04 | F33: Rentrer | G33: Compromettre un fournisseur de support/analytique, ou déclencher une panne au niveau d'un fournisseur. | H33: T1199 Trusted Relationship
A34: OS-08 | B34: SS-04 | C34: Un incident chez un sous-traitant ou hyperscaler se propage à GitLab | D34: R-04 | F34: Trouver | G34: Utiliser les intégrations (ticketing, chaînes de données, passerelles IA) détenant des données ou identifiants liés aux clients. | H34: T1552 Unsecured Credentials
A35: OS-08 | B35: SS-04 | C35: Un incident chez un sous-traitant ou hyperscaler se propage à GitLab | D35: R-04 | F35: Exploiter | G35: Exfiltrer des données de support clients ou dégrader les services GitLab dépendant du fournisseur. | H35: T1530 Data from Cloud Storage
A36: OS-09 | B36: SS-08 | C36: Un interne ou un agent de support externalisé abuse de son accès légitime | D36: R-08 | E36: 2 | F36: Connaître | G36: L'interne connaît déjà les systèmes et les circuits d'approbation. | H36: - | I36: Approbations d'accès, revues et retrait à la cessation d'emploi (E-16) ; effectif PEO et prestataire reconnu (E-01). | J36: Le filtrage des candidats, la surveillance des internes privilégiés et les contraintes du support externalisé ne sont pas vérifiables publiquement.
A37: OS-09 | B37: SS-08 | C37: Un interne ou un agent de support externalisé abuse de son accès légitime | D37: R-08 | F37: Rentrer | G37: Utilise ses droits existants, ou manipule un collègue pour obtenir des accès supplémentaires. | H37: T1078 Valid Accounts
A38: OS-09 | B38: SS-08 | C38: Un interne ou un agent de support externalisé abuse de son accès légitime | D38: R-08 | F38: Trouver | G38: Recherche des données clients à forte valeur ou des fonctions d'administration. | H38: T1213 Data from Information Repositories
A39: OS-09 | B39: SS-08 | C39: Un interne ou un agent de support externalisé abuse de son accès légitime | D39: R-08 | F39: Exploiter | G39: Extrait des données ou sabote la configuration. | H39: T1567 Exfiltration over Web Service / T1098 Account Manipulation
A40: OS-10 | B40: SS-11 | C40: Un attaquant exploite le handbook et les issues publics pour y trouver des détails opérationnels exploitables | D40: R-13 | E40: 3 | F40: Connaître | G40: Parcourir handbook, trackers d'issues, merge requests, feuille de route et blog. | H40: T1593 Search Open Websites/Domains | I40: La transparence est délibérée et bornée par des sections internes du handbook ; le 10-K reconnaît la « transparence responsable » (E-02). | J40: Les garde-fous automatisés pour le contenu public (détection de secrets/PII, portes de classification) ne sont pas documentés publiquement.
...

Sheet Registre_Risques
A1: Registre des risques (risque inhérent)
A2: Score = Impact x Vraisemblance (formule). Niveaux : Critique >= 20, Élevé 15-19, Moyen 8-14, Faible <= 7. Cellules grises en gras = jugement de l'analyste.
A4: ID | B4: Risque | C4: Description | D4: SS | E4: OS | F4: Événements redoutés | G4: Valeurs métier | H4: Impact (1-5) | I4: Vraisemblance (1-5) | J4: Score de risque | K4: Priorité | L4: Justification de la vraisemblance (preuves publiques) | M4: Preuves | N4: Responsable du risque (proposé)
A5: R-01 | B5: Compromission d'identité privilégiée | C5: Compromission d'identités de collaborateurs ou d'administration (y compris vol de session/jeton) donnant accès à la production, aux organisations cloud, aux opérateurs Dedicated ou aux éléments de signature. | D5: SS-01 | E5: OS-01 | F5: ER-08, ER-01 | G5: VM-01, VM-02, VM-04, VM-07 | H5: 5 | I5: 4 | J5: =H5*I5 -> 20 | K5: =IF(J5>=20,"Critique",IF(J5>=15,"Élevé",IF(J5>=8,"Moyen","Faible"))) -> Critique | L5: Les campagnes d'infostealers et de vol de session sont courantes contre les équipes d'ingénierie distantes ; les notations externes signalent des détections d'infostealers liées à l'organisation ; les mesures de sessions privilégiées ne sont pas démontrées publiquement. | M5: E-01, E-16, E-17, E-29, E-03 | N5: Responsable Identités et Accès (proposé)
A6: R-02 | B6: Exploitation de vulnérabilités produit critiques | C6: Une faille critique de GitLab (lecture de fichier pré-auth, désérialisation, RCE CI/CD) est exploitée contre GitLab.com, Dedicated ou la base auto-hébergée. | D6: SS-03 | E6: OS-03 | F6: ER-01, ER-07 | G6: VM-01, VM-02, VM-03, VM-04 | H6: 5 | I6: 4 | J6: =H6*I6 -> 20 | K6: =IF(J6>=20,"Critique",IF(J6>=15,"Élevé",IF(J6>=8,"Moyen","Faible"))) -> Critique | L6: Deux failles GitLab inscrites au KEV en 30 mois (CVE-2023-7028 ; CVE-2026-85706 avec exploitation en quelques jours) et d'autres correctifs RCE critiques le 23 sept. 2026. | M6: E-20, E-22, E-23, E-24, E-26, E-32 | N6: VP Sécurité produit (proposé)
A7: R-03 | B7: Compromission de la chaîne d'approvisionnement logicielle du produit GitLab | C7: Du code ou un artefact malveillant est introduit via les contributeurs, dépendances, build ou infrastructure de release. | D7: SS-02 | E7: OS-02 | F7: ER-02 | G7: VM-03, VM-01 | H7: 5 | I7: 3 | J7: =H7*I7 -> 15 | K7: =IF(J7>=20,"Critique",IF(J7>=15,"Élevé",IF(J7>=8,"Moyen","Faible"))) -> Élevé | L7: Modèle open-core avec plus de 5 200 contributeurs et forte utilisation de dépendances ; les attaques de chaîne d'approvisionnement sont répandues dans le secteur ; mesures d'intégrité de build non démontrées publiquement. | M7: E-01, E-02 | N7: VP Ingénierie / Ingénierie de release (proposé)
A8: R-04 | B8: Défaillance ou compromission de tiers et de fournisseurs cloud | C8: Une violation ou panne chez Google Cloud, AWS, les fournisseurs de modèles d'IA ou les sous-traitants de support affecte les services ou données de GitLab. | D8: SS-04 | E8: OS-08 | F8: ER-03, ER-01 | G8: VM-01, VM-02, VM-05, VM-07 | H8: 4 | I8: 3 | J8: =H8*I8 -> 12 | K8: =IF(J8>=20,"Critique",IF(J8>=15,"Élevé",IF(J8>=8,"Moyen","Faible"))) -> Moyen | L8: Forte dépendance à deux hyperscalers et à plusieurs fournisseurs d'IA/support ; concentration et plans de sortie non vérifiables publiquement. | M8: E-02, E-09, E-10, E-12 | N8: Responsable Risques tiers (proposé)
A9: R-05 | B9: Interruption majeure de service ou perte de données | C9: Panne prolongée de GitLab.com, attaque destructrice ou défaillance régionale avec reprise lente ou incomplète. | D9: SS-07 | E9: OS-06 | F9: ER-03 | G9: VM-01 | H9: 5 | I9: 3 | J9: =H9*I9 -> 15 | K9: =IF(J9>=20,"Critique",IF(J9>=15,"Élevé",IF(J9>=8,"Moyen","Faible"))) -> Élevé | L9: Exploitation mono-région décrite dans les documents de conception, reprise régionale historiquement non validée de bout en bout ; atténuée par les Game Days, sauvegardes multi-régions et tests de restauration quotidiens. | M9: E-12, E-13, E-14, E-15, E-01 | N9: VP Infrastructure (proposé)
A10: R-06 | B10: Détournement des fonctions d'IA et des agents | C10: Injection de prompt, agents/jetons sur-privilégiés ou faiblesses de la chaîne d'approvisionnement de l'IA conduisent à des fuites de données ou modifications de code malveillantes. | D10: SS-05 | E10: OS-04 | F10: ER-05 | G10: VM-05, VM-04 | H10: 4 | I10: 4 | J10: =H10*I10 -> 16 | K10: =IF(J10>=20,"Critique",IF(J10>=15,"Élevé",IF(J10>=8,"Moyen","Faible"))) -> Élevé | L10: Des recherches publiées ont déjà démontré l'exfiltration ; les agents autonomes étendent la surface ; les correctifs de septembre 2026 touchent Duo, GraphQL et les périmètres MCP. | M10: E-02, E-23, E-26, E-27 | N10: Responsable Sécurité de l'IA (proposé)
A11: R-07 | B11: Compromission du plan de contrôle Dedicated ou de l'isolation des tenants | C11: L'accès opérateur ou une faille du plan de gestion donne une portée multi-tenant dans GitLab Dedicated. | D11: SS-06 | E11: OS-05 | F11: ER-04 | G11: VM-02 | H11: 5 | I11: 2 | J11: =H11*I11 -> 10 | K11: =IF(J11>=20,"Critique",IF(J11>=15,"Élevé",IF(J11>=8,"Moyen","Faible"))) -> Moyen | L11: Une conception d'isolation robuste et le contrôle des clients régulés réduisent la vraisemblance, mais l'impact est multi-tenant par construction. | M11: E-10, E-11, E-06 | N11: Directeur Ingénierie Dedicated (proposé)
A12: R-08 | B12: Abus d'accès privilégié ou de support par un interne | C12: Un salarié, prestataire, personnel PEO ou de support externalisé abuse d'un accès légitime. | D12: SS-08 | E12: OS-09 | F12: ER-08, ER-01 | G12: VM-07, VM-04 | H12: 4 | I12: 2 | J12: =H12*I12 -> 8 | K12: =IF(J12>=20,"Critique",IF(J12>=15,"Élevé",IF(J12>=8,"Moyen","Faible"))) -> Moyen | L12: Les modèles d'effectif larges accroissent l'exposition ; une politique d'accès et des mesures de retrait des droits existent. | M12: E-01, E-16, E-09 | N12: Responsable Assurance sécurité / RH (proposé)
A13: R-09 | B13: Abus des runners CI partagés et évasion entre tenants | C13: Des jobs malveillants sortent de l'isolation, capturent des secrets ou détournent du calcul partagé. | D13: SS-09 | E13: OS-07 | F13: ER-09 | G13: VM-01, VM-04 | H13: 4 | I13: 3 | J13: =H13*I13 -> 12 | K13: =IF(J13>=20,"Critique",IF(J13>=15,"Élevé",IF(J13>=8,"Moyen","Faible"))) -> Moyen | L13: L'exécution du code client est inhérente au produit ; l'abus de l'offre gratuite est un schéma persistant. | M13: E-02, E-05 | N13: Directeur Plateforme Runners (proposé)
A14: R-10 | B14: Écart d'adoption des correctifs exposant les clients auto-hébergés et la réputation de GitLab | C14: Les clients ne corrigent pas (ou exécutent des versions non supportées) après divulgation, entraînant une exploitation de masse et une atteinte à la réputation de GitLab. | D14: SS-03 | E14: OS-03 | F14: ER-07 | G14: VM-03, VM-07 | H14: 4 | I14: 4 | J14: =H14*I14 -> 16 | K14: =IF(J14>=20,"Critique",IF(J14>=15,"Élevé",IF(J14>=8,"Moyen","Faible"))) -> Élevé | L14: Deux semaines après la faille KEV de 2024, des milliers d'instances restaient vulnérables ; en 2026, des correctifs ont été rétroportés vers des branches en fin de vie. | M14: E-21, E-25, E-22 | N14: VP Sécurité produit / Support (proposé)
A15: R-11 | B15: Défaut de continuité de la gouvernance de la sécurité | C15: Une transition de direction et une croissance rapide réduisent la clarté de la responsabilité des risques, le reporting d'indicateurs et le rythme d'assurance. | D15: SS-10 | E15: - | F15: ER-06 | G15: VM-06, VM-07 | H15: 3 | I15: 3 | J15: =H15*I15 -> 9 | K15: =IF(J15>=20,"Critique",IF(J15>=15,"Élevé",IF(J15>=8,"Moyen","Faible"))) -> Moyen | L15: Poste de RSSI laissé vacant le 26 févr. 2026 avec un intérimaire en place ; programme décrit comme se poursuivant normalement. | M15: E-03, E-04, E-31 | N15: Comité d'audit / DG (proposé)
A16: R-12 | B16: Expiration ou érosion des certifications et de l'éligibilité aux marchés régulés | C16: Transitions de normes manquées, écarts de périmètre ou constats avec réserves compromettent les ventes publiques et régulées. | D16: SS-10 | E16: - | F16: ER-06 | G16: VM-06 | H16: 3 | I16: 2 | J16: =H16*I16 -> 6 | K16: =IF(J16>=20,"Critique",IF(J16>=15,"Élevé",IF(J16>=8,"Moyen","Faible"))) -> Faible | L16: Portefeuille de certifications solide, mais les pages publiques mélangent des éditions ISO et FedRAMP High reste prévu. | M16: E-05, E-06, E-07, E-30 | N16: Directeur Conformité sécurité (proposé)
A17: R-13 | B17: Sur-divulgation due à la transparence radicale | C17: Le handbook, les issues et la feuille de route publics fuitent des détails opérationnels ou de sécurité, ou des secrets. | D17: SS-11 | E17: OS-10 | F17: ER-10 | G17: VM-07, VM-03 | H17: 3 | I17: 3 | J17: =H17*I17 -> 9 | K17: =IF(J17>=20,"Critique",IF(J17>=15,"Élevé",IF(J17>=8,"Moyen","Faible"))) -> Moyen | L17: La transparence est une valeur centrale et le 10-K signale l'exactitude du handbook et les conséquences involontaires comme un risque. | M17: E-02 | N17: Responsable Assurance sécurité (proposé)
B19: Synthèse par priorité
B20: Critique | C20: =COUNTIF($K$5:$K$17,B20) -> 2
B21: Élevé | C21: =COUNTIF($K$5:$K$17,B21) -> 4
B22: Moyen | C22: =COUNTIF($K$5:$K$17,B22) -> 6
B23: Faible | C23: =COUNTIF($K$5:$K$17,B23) -> 1
B24: Total des risques | C24: =SUM(C20:C23) -> 13
B25: Score inhérent moyen | C25: =ROUND(AVERAGE(J5:J17),1) -> 12.9

Sheet AT5_Traitement
A1: Atelier 5 - Décisions de traitement et risque résiduel
A2: Résiduel = cible après la feuille de route de 24 mois. Le score inhérent provient de Registre_Risques. Impact/vraisemblance résiduels = saisies sur fond gris.
A4: Risque | B4: Intitulé du risque | C4: Score inhérent | D4: Décision | E4: Mesures de traitement | F4: Exigences PSSI | G4: Actions de la feuille de route | H4: Impact résiduel | I4: Vraisemblance résiduelle | J4: Score résiduel | K4: Niveau résiduel | L4: Responsable du risque / autorité d'acceptation | M4: Revue
A5: R-01 | B5: Compromission d'identité privilégiée | C5: =INDEX(Registre_Risques!$J$5:$J$17,MATCH(A5,Registre_Risques!$A$5:$A$17,0)) -> 20 | D5: Réduire | E5: Inventaire des accès privilégiés Tier-0 ; MFA résistant à l'hameçonnage et sessions courtes ; élévation juste-à-temps ; hygiène des identités machines ; détection d'activité privilégiée anormale. | F5: IAM-01, IAM-02, IAM-04, MON-01 | G5: A-01, A-04, A-05, A-09, A-10, A-11, A-12, A-16, A-21 | H5: 5 | I5: 2 | J5: =H5*I5 -> 10 | K5: =IF(J5>=20,"Critique",IF(J5>=15,"Élevé",IF(J5>=8,"Moyen","Faible"))) -> Moyen | L5: RSSI (intérim puis titulaire) ; comité d'audit informé | M5: Trimestrielle
A6: R-02 | B6: Exploitation de vulnérabilités produit critiques | C6: =INDEX(Registre_Risques!$J$5:$J$17,MATCH(A6,Registre_Risques!$A$5:$A$17,0)) -> 20 | D6: Réduire | E6: Réponse aux vulnérabilités critiques plus rapide et répétée ; durcissement du développement sécurisé des composants à haut risque (authz, parseurs, interpréteurs CI/CD) ; réduction d'exposition en périphérie SaaS ; playbook KEV. | F6: SSC-03, SSC-04, RES-03 | G6: A-02, A-03, A-06, A-08, A-16, A-17, A-22 | H6: 5 | I6: 3 | J6: =H6*I6 -> 15 | K6: =IF(J6>=20,"Critique",IF(J6>=15,"Élevé",IF(J6>=8,"Moyen","Faible"))) -> Élevé | L6: RSSI ; risque résiduel Élevé accepté par le comité d'audit avec suivi | M6: Mensuelle (par cycle de release)
A7: R-03 | B7: Compromission de la chaîne d'approvisionnement logicielle du produit GitLab | C7: =INDEX(Registre_Risques!$J$5:$J$17,MATCH(A7,Registre_Risques!$A$5:$A$17,0)) -> 15 | D7: Réduire | E7: Provenance et signature vérifiables des builds, builders éphémères hermétiques, approbation de release à deux personnes, comptes de mainteneurs durcis, gouvernance des dépendances. | F7: SSC-01, SSC-02, IAM-01 | G7: A-09, A-19 | H7: 5 | I7: 2 | J7: =H7*I7 -> 10 | K7: =IF(J7>=20,"Critique",IF(J7>=15,"Élevé",IF(J7>=8,"Moyen","Faible"))) -> Moyen | L7: RSSI / VP Ingénierie | M7: Trimestrielle
A8: R-04 | B8: Défaillance ou compromission de tiers et de fournisseurs cloud | C8: =INDEX(Registre_Risques!$J$5:$J$17,MATCH(A8,Registre_Risques!$A$5:$A$17,0)) -> 12 | D8: Réduire + Transférer | E8: Analyse de concentration et de sortie, plans en mode dégradé, clauses contractuelles de sécurité et de notification, revue de la cyber-assurance. | F8: TPM-01, TPM-02 | G8: A-13, A-14, A-23 | H8: 4 | I8: 2 | J8: =H8*I8 -> 8 | K8: =IF(J8>=20,"Critique",IF(J8>=15,"Élevé",IF(J8>=8,"Moyen","Faible"))) -> Moyen | L8: RSSI / DAF | M8: Semestrielle
A9: R-05 | B9: Interruption majeure de service ou perte de données | C9: =INDEX(Registre_Risques!$J$5:$J$17,MATCH(A9,Registre_Risques!$A$5:$A$17,0)) -> 15 | D9: Réduire | E9: Tests de reprise régionale de bout en bout, sauvegardes immuables inter-comptes, réduction du rayon d'impact (cellules), attestation publique des RTO/RPO. | F9: RES-01, RES-02, RES-03 | G9: A-13, A-18, A-23 | H9: 5 | I9: 2 | J9: =H9*I9 -> 10 | K9: =IF(J9>=20,"Critique",IF(J9>=15,"Élevé",IF(J9>=8,"Moyen","Faible"))) -> Moyen | L9: VP Infrastructure ; RSSI | M9: Trimestrielle
A10: R-06 | B10: Détournement des fonctions d'IA et des agents | C10: =INDEX(Registre_Risques!$J$5:$J$17,MATCH(A10,Registre_Risques!$A$5:$A$17,0)) -> 16 | D10: Réduire | E10: Modélisation des menaces de l'IA, jetons d'agents et MCP au moindre privilège, approbation humaine des actions sensibles, durcissement des canaux de sortie, red teaming continu de l'IA. | F10: AI-01, AI-02, AI-03 | G10: A-03, A-14, A-22 | H10: 4 | I10: 3 | J10: =H10*I10 -> 12 | K10: =IF(J10>=20,"Critique",IF(J10>=15,"Élevé",IF(J10>=8,"Moyen","Faible"))) -> Moyen | L10: Responsable Sécurité de l'IA ; RSSI | M10: Trimestrielle
A11: R-07 | B11: Compromission du plan de contrôle Dedicated ou de l'isolation des tenants | C11: =INDEX(Registre_Risques!$J$5:$J$17,MATCH(A11,Registre_Risques!$A$5:$A$17,0)) -> 10 | D11: Réduire | E11: Revue de durcissement du plan de contrôle, test d'intrusion indépendant des chemins inter-tenants, accès opérateur JIT. | F11: CLD-02, IAM-01 | G11: A-05, A-11, A-24 | H11: 5 | I11: 1 | J11: =H11*I11 -> 5 | K11: =IF(J11>=20,"Critique",IF(J11>=15,"Élevé",IF(J11>=8,"Moyen","Faible"))) -> Faible | L11: Directeur Dedicated ; RSSI | M11: Semestrielle
A12: R-08 | B12: Abus d'accès privilégié ou de support par un interne | C12: =INDEX(Registre_Risques!$J$5:$J$17,MATCH(A12,Registre_Risques!$A$5:$A$17,0)) -> 8 | D12: Réduire | E12: Programme de risque interne, référentiel d'accès des prestataires/PEO, surveillance de l'activité privilégiée. | F12: IAM-03, PPL-01, PPL-02 | G12: A-04, A-12, A-21 | H12: 3 | I12: 2 | J12: =H12*I12 -> 6 | K12: =IF(J12>=20,"Critique",IF(J12>=15,"Élevé",IF(J12>=8,"Moyen","Faible"))) -> Faible | L12: Responsable Assurance sécurité ; RH | M12: Semestrielle
A13: R-09 | B13: Abus des runners CI partagés et évasion entre tenants | C13: =INDEX(Registre_Risques!$J$5:$J$17,MATCH(A13,Registre_Risques!$A$5:$A$17,0)) -> 12 | D13: Réduire | E13: Durcissement de l'isolation des runners et analytique d'abus. | F13: CLD-03 | G13: A-20 | H13: 3 | I13: 2 | J13: =H13*I13 -> 6 | K13: =IF(J13>=20,"Critique",IF(J13>=15,"Élevé",IF(J13>=8,"Moyen","Faible"))) -> Faible | L13: Directeur Plateforme Runners | M13: Semestrielle
A14: R-10 | B14: Écart d'adoption des correctifs exposant les clients auto-hébergés et la réputation de GitLab | C14: =INDEX(Registre_Risques!$J$5:$J$17,MATCH(A14,Registre_Risques!$A$5:$A$17,0)) -> 16 | D14: Réduire | E14: Normes d'avis aux clients, politique de versions supportées, incitations fondées sur la télémétrie, publication d'indicateurs de délai de correction. | F14: SSC-03, SSC-05, CMP-02 | G14: A-02, A-08, A-17 | H14: 4 | I14: 3 | J14: =H14*I14 -> 12 | K14: =IF(J14>=20,"Critique",IF(J14>=15,"Élevé",IF(J14>=8,"Moyen","Faible"))) -> Moyen | L14: VP Sécurité produit ; Support | M14: À chaque release critique
